Workbook

Sheet 1. Submittal
A1: Filename | B1: Issue Status | C1: Revision | D1: Revision Date | E1: Description / Title | F1: Discipline | G1: Category | H1: Asset / ID Number | I1: Project | J1: Plant | K1: Department Code | L1: Document Type | M1: Vendor Name | N1: Location | O1: Department Name
A2: E-7-160.51.27.276-074-06_Single Line Distribution Diagram.dwg | O2: =IFERROR(VLOOKUP(K2,'2. Buzzi Admin Only'!Q:R,2,0),"")
A3: 84957r0.PDF | D3: 12/04/07 | E3: HANDRAIL | F3: Structural | G3: S | H3: M 84957 | L3: Drawings | M3: SBN | O3: =IFERROR(VLOOKUP(K3,'2. Buzzi Admin Only'!Q:R,2,0),"")
A4: 63902.PDF | D4: 08/15/00 | E4: S.S. 420 | F4: Structural | G4: D | H4: M-S-01-S-25 | L4: Drawings | M4: QUALICO STEEL CO, INC. | O4: =IFERROR(VLOOKUP(K4,'2. Buzzi Admin Only'!Q:R,2,0),"")
A5: EXIST CLINKER Wall D5.1 Final 09-20-08.pdf | D5: 09/30/08 | E5: ROOF BOTTOM EAVE SECTION, ROOF RAKE SECTION, CORNER SECTION, ROOF TOP EAVE SECTION, SILL SECTION, BASE SECTION, JAMB SECTION, HEAD SECTION, PANEL LAP DETAIL | F5: Structural | G5: R | L5: Drawings | M5: CRU-CON ENGINEERING | O5: =IFERROR(VLOOKUP(K5,'2. Buzzi Admin Only'!Q:R,2,0),"")
A6: 22231R1.PDF | O6: =IFERROR(VLOOKUP(K6,'2. Buzzi Admin Only'!Q:R,2,0),"")
A7: 92104.PDF | B7: IFA | D7: 06/01/07 | E7: BILL OF MATERIAL | F7: Structural | G7: S | H7: 921041C1 | L7: Drawings | M7: M.E.I. | O7: =IFERROR(VLOOKUP(K7,'2. Buzzi Admin Only'!Q:R,2,0),"")
A8: 11107r4.PDF | C8: A | D8: 05/21/00 | E8: UPRIGHT 14-11 | F8: Structural | G8: D | H8: 1189P | L8: Drawings | M8: GARDNER, INC. | O8: =IFERROR(VLOOKUP(K8,'2. Buzzi Admin Only'!Q:R,2,0),"")
A9: 26221A.PDF | O9: =IFERROR(VLOOKUP(K9,'2. Buzzi Admin Only'!Q:R,2,0),"")
A10: 66902Ar1.pdf | E10: C-21-00001 | F10: Structural | G10: A | L10: Drawings | M10: QUALICO STEEL CO., INC. | O10: =IFERROR(VLOOKUP(K10,'2. Buzzi Admin Only'!Q:R,2,0),"")
A11: 93208r0.PDF | D11: 04/01/07 | E11: GRID BEAM | F11: Structural | G11: S | H11: 932081 | J11: River Cement | L11: Drawings | M11: QUALICO STEEL CO. INC. | O11: =IFERROR(VLOOKUP(K11,'2. Buzzi Admin Only'!Q:R,2,0),"")
A12: 61969r0.PDF | C12: 0 | K12: 550 | O12: =IFERROR(VLOOKUP(K12,'2. Buzzi Admin Only'!Q:R,2,0),"") -> Bags Cement Shipping (Packing & Palletizers)
A13: G51 REV-0.pdf | D13: 08/23/27 | E13: BILL OF MATERIAL | F13: Structural | G13: D | L13: Drawings | M13: GULP INC. | O13: =IFERROR(VLOOKUP(K13,'2. Buzzi Admin Only'!Q:R,2,0),"")
A14: 17413.PDF | B14: IFA | D14: 01/10/07 | E14: WELDED ASSEMBLY FOR BRACE | F14: Structural | G14: D | H14: C-1321 (V12) | L14: Drawings | M14: QUALITY STEEL CO. INC. | O14: =IFERROR(VLOOKUP(K14,'2. Buzzi Admin Only'!Q:R,2,0),"")
A15: 16415R1.PDF | E15: BILL OF MATERIAL | F15: Structural | G15: G | L15: Listings | O15: =IFERROR(VLOOKUP(K15,'2. Buzzi Admin Only'!Q:R,2,0),"")
A16: 14404.PDF | D16: 12/18/07 | E16: BOTTOM BRACE | F16: Structural | G16: S | H16: 14404 | J16: River Cement | L16: Drawings | M16: QUALICO STEEL CO. INC. | O16: =IFERROR(VLOOKUP(K16,'2. Buzzi Admin Only'!Q:R,2,0),"")
A17: 20215.PDF | B17: IFA | D17: 02/12/07 | E17: BEAM | F17: Structural | G17: S | H17: 2021S | J17: River Cement | L17: Drawings | M17: QUALICO STEEL CO. INC. | O17: =IFERROR(VLOOKUP(K17,'2. Buzzi Admin Only'!Q:R,2,0),"")
A18: 16443.PDF | E18: BILL OF MATERIAL | F18: Structural | G18: S | L18: Drawings | O18: =IFERROR(VLOOKUP(K18,'2. Buzzi Admin Only'!Q:R,2,0),"")
A19: 82416.pdf | B19: IFA | D19: 06/08/17 | E19: METAL BRACKETING | F19: Structural | G19: D | H19: 6241SCD | L19: Drawings | M19: QUALICO STEEL CO. INC. | O19: =IFERROR(VLOOKUP(K19,'2. Buzzi Admin Only'!Q:R,2,0),"")
A20: 146058PI9004.dwg | O20: =IFERROR(VLOOKUP(K20,'2. Buzzi Admin Only'!Q:R,2,0),"")
A21: MN509565-SP01_Rev0.pdf | D21: 01/01/23 | L21: Drawings | O21: =IFERROR(VLOOKUP(K21,'2. Buzzi Admin Only'!Q:R,2,0),"")
A22: MN509565-SP02_Rev0.pdf | E22: SPLICE PLATE STRINGER MK. 52.2 | F22: Structural | G22: D | H22: M0005001-SP2 | L22: Drawings | M22: DISEÑO DE MAQUINAS E INDUSTRIAS INDUSTRIALES, S.A. DE C.V. | O22: =IFERROR(VLOOKUP(K22,'2. Buzzi Admin Only'!Q:R,2,0),"")
A23: MN509560-TT03_Rev0.pdf | D23: 01/11/21 | E23: TOWER STEEL STRUCTURE | F23: Structural | G23: A | H23: M000001775 | L23: Drawings | O23: =IFERROR(VLOOKUP(K23,'2. Buzzi Admin Only'!Q:R,2,0),"")
A24: MN509565-BNT03_Rev0.pdf | E24: ASSEMBLY LIST | F24: Structural | G24: A | L24: Listings | O24: =IFERROR(VLOOKUP(K24,'2. Buzzi Admin Only'!Q:R,2,0),"")
A25: y-394691_001.dwg | O25: =IFERROR(VLOOKUP(K25,'2. Buzzi Admin Only'!Q:R,2,0),"")
A26: MN509565-BNT02_Rev0.pdf | E26: BENT MK. 37.2 | F26: Structural | G26: D | H26: M0000000187F0 | L26: Drawings | M26: SISTEMA DE MAQUINAS INDUSTRIALES S.A. DE C.V. | O26: =IFERROR(VLOOKUP(K26,'2. Buzzi Admin Only'!Q:R,2,0),"")
A27: MN509565-ES01_Rev2.pdf | C27: 0 | D27: 02/14/24 | E27: ELEVATION ON GRID B | F27: Structural | G27: A | H27: EQ_MN509565 | L27: Drawings | M27: Holcim | O27: =IFERROR(VLOOKUP(K27,'2. Buzzi Admin Only'!Q:R,2,0),"")
A28: MN509565-BNT01_Rev0.pdf | D28: 05/27/21 | E28: BENT MK. 37.1 | F28: Structural | G28: A | H28: M03000-BT31 | L28: Drawings | M28: dm DISEÑO DE MAQUINAS INDUSTRIALES S.A. DE C.V. | O28: =IFERROR(VLOOKUP(K28,'2. Buzzi Admin Only'!Q:R,2,0),"")
A29: MN509560-SG02_Rev0.pdf | E29: STRINGER STANDARD SECTION 5800mm SL. 1/1 | F29: Structural | G29: A | H29: MN5095580 | L29: Drawings | M29: DISENO DE MAQUINAS INDUSTRIALES, S.A. DE C.V. | O29: =IFERROR(VLOOKUP(K29,'2. Buzzi Admin Only'!Q:R,2,0),"")
A30: ID 2949 - Paint_Specification_Primer.pdf | D30: 12/11 | E30: KEM BOND® HS UNIVERSAL METAL PRIMER | L30: Cut Sheets | M30: Sherwin-Williams | O30: =IFERROR(VLOOKUP(K30,'2. Buzzi Admin Only'!Q:R,2,0),"")
A31: ID 2950 - Paint_Specification_Final_Coat.pdf | C31: 2.24 | D31: 07/10/null | E31: METALASTIC® DTM ACRYLIC MODIFIED ENAMEL PRODUCT INFORMATION | L31: Cut Sheets | M31: Sherwin Williams | O31: =IFERROR(VLOOKUP(K31,'2. Buzzi Admin Only'!Q:R,2,0),"")
A32: D_56-01974_R0.dwg | O32: =IFERROR(VLOOKUP(K32,'2. Buzzi Admin Only'!Q:R,2,0),"")
A33: ID 2449 - Pump-Cardox_Room_Sketch.pdf | E33: Plan View and Sections of Electrical Room, Pump Room, Cargo Room, and Analyzer Shelter | F33: Electrical | G33: G | H33: 2648 | L33: Drawings | O33: =IFERROR(VLOOKUP(K33,'2. Buzzi Admin Only'!Q:R,2,0),"")
A34: MN509565-SG01_Rev0.pdf | B34: PRE | C34: A | D34: 12/21/22 | E34: ELEVATIONS AND PLAN VIEW | F34: Structural | G34: A | H34: JN09445 | L34: Drawings | O34: =IFERROR(VLOOKUP(K34,'2. Buzzi Admin Only'!Q:R,2,0),"")
A35: D_59-00254_1.dwg | B35: APR | C35: 0 | D35: 01/15/24 | E35: VALVULA SOPORTE PARA CONTRAFLANJA | F35: Mechanical | G35: M | H35: 3P-2024 | L35: Drawings | O35: =IFERROR(VLOOKUP(K35,'2. Buzzi Admin Only'!Q:R,2,0),"")
A36: ID 2948 - Equipment_List Rev 1.pdf | C36: 1 | D36: 03/09/15 | E36: Equipment List | F36: Mechanical | G36: F | H36: 304130.01 | L36: Listings | M36: Lechler, Inc. | O36: =IFERROR(VLOOKUP(K36,'2. Buzzi Admin Only'!Q:R,2,0),"")
A37: MN509565-SG02_Rev0.pdf | B37: PRE | C37: P | D37: 02/14/18 | E37: SISTEMA ESTEREO ELEVACION GRID A, B, C | F37: Structural | G37: A | H37: EQ_MN009565 | L37: Drawings | M37: MACQUINAS INDUSTRIALES, S.A. DE C.V. | O37: =IFERROR(VLOOKUP(K37,'2. Buzzi Admin Only'!Q:R,2,0),"")
A38: D_59-00257_0.dwg | B38: IFC | C38: 0 | D38: 11/20/00 | E38: TRONCO CONICO Ø 281 x 42 x 2 m VALVOLA A TAMPORE CHIUSO ± 3 VIE | F38: Mechanical | G38: M | L38: Drawings | M38: BORRANEI S.R.L. | O38: =IFERROR(VLOOKUP(K38,'2. Buzzi Admin Only'!Q:R,2,0),"")
A39: D_59-00260_1.dwg | B39: IFC | D39: 01/20/00 | E39: VALVOLE PER GAS (Gas Valves) | F39: Mechanical | G39: P | H39: 59-06260 | L39: Drawings | M39: BORRANI S.p.A. | O39: =IFERROR(VLOOKUP(K39,'2. Buzzi Admin Only'!Q:R,2,0),"")
A40: D_59-00256_0.dwg | C40: A | D40: 05/12/21 | E40: VALVULA DE PASO PARA MESA | F40: Mechanical | G40: M | H40: 4003-3LZ-24 | L40: Drawings | O40: =IFERROR(VLOOKUP(K40,'2. Buzzi Admin Only'!Q:R,2,0),"")
...

Sheet Sheet1

Sheet 2. Buzzi Admin Only
A1: Issue Status | C1: Discipline | E1: Architectural | F1: Civil | G1: Electrical | H1: Geotechnical | I1: Mechanical | J1: Process | K1: Quarry | L1: Structural | N1: Plant | O1: Location | Q1: Department Code | R1: Department Name | T1: Document Type
A2: AB- As-Built | C2: Architectural | E2: A | F2: B | G2: A | H2: N/A | I2: C | J2: C | K2: G | L2: A | N2: Alamo Cement | O2: San Antonio, TX | Q2: -TBD- | R2: -TBD- | T2: Conceptual Docs
A3: APR- Approved | C3: Civil | E3: C | F3: C | G3: B | I3: D | J3: E | K3: M | L3: C | N3: Amarillo Terminal | O3: Amarillo, TX | Q3: 100 | R3: Quarry | T3: Correspondences
A4: BID- For Bid Use only | C4: Electrical | E4: D | F4: D | G4: C | I4: E | J4: F | K4: P | L4: D | N4: Bonner Springs Terminal | O4: Bonner Springs, KS | Q4: 110 | R4: Limestone Quarry | T4: Cut Sheets
A5: CRT- Certified | C5: Geotechnical | E5: G | F5: E | G5: D | I5: F | J5: G | K5: Q | L5: G | N5: Brandon Terminal | O5: Brandon, MS | Q5: 200 | R5: Crushing | T5: Drawings
A6: FYU- For Your Use | C6: Mechanical | E6: L | F6: G | G6: E | I6: G | J6: R | K6: V | L6: L | N6: Burnside Terminal | O6: Darrow, LA | Q6: 201 | R6: Crushing #1 | T6: Listings
A7: IFA- Issued For Approval | C7: Process | E7: P | F7: H | G7: F | I7: H | J7: S | K7: X | L7: M | N7: Cape Girardeau Cement | O7: Cape Girardeau, MO | Q7: 202 | R7: Crushing #2 | T7: Manuals
A8: IFC- Issued For Construction | C8: Quarry | E8: R | F8: L | G8: G | I8: L | J8: V | K8: Y | L8: R | N8: Cincinnati Terminal | O8: Cincinnati, OH | Q8: 203 | R8: Crushing #3 | T8: Misc. Vendor Docs
A9: IFR- Issued For Review and Comment | C9: Structural | E9: S | F9: R | G9: H | I9: M | J9: X | L9: S | N9: College Park Terminal | O9: College Park, GA | Q9: 205 | R9: Additives Crushing | T9: Reports
A10: PRE- Preliminary | E10: V | F10: S | G10: I | I10: P | J10: Y | L10: V | N10: Dallas Terminal | O10: Dallas, TX | Q10: 210 | R10: Raw Materials Unloading | T10: Specifications
A11: REC- For Records | E11: W | F11: T | G11: J | I11: U | J11: Z | L11: X | N11: Dawsonville Terminal | O11: Dawsonville, GA | Q11: 211 | R11: Barge Unloading | T11: Studies
A12: RFE- Released for Engr | E12: X | F12: U | G12: K | I12: V | L12: Y | N12: Elkhart Terminal | O12: Elkhart, IN | Q12: 212 | R12: Rail Unloading | T12: Submittals
A13: RWC- Returned with Comments | E13: Y | F13: V | G13: L | I13: X | N13: Elmira Terminal | O13: Elmira, MI | Q13: 213 | R13: Additives Unloading | T13: Transmittals
E14: Z | F14: X | G14: M | I14: Y | N14: Fort Wayne Terminal | O14: Fort Wayne, IN | Q14: 214 | R14: Barge Loading
F15: Y | G15: O | I15: Z | N15: Gainesville Terminal | O15: Gainesville, TX | Q15: 220 | R15: Raw Materials Pre-Blending, Handling & Storage
F16: Z | G16: P | N16: Grandville Terminal | O16: Grandville, MI | Q16: 221 | R16: Pre-Blending
G17: Q | N17: Greencastle Cement | O17: Greencastle, IN | Q17: 222 | R17: Raw Material Proportioning and Mill Feed
G18: R | N18: Hercules Cement | O18: Stockertown, PA | Q18: 230 | R18: Raw Grinding
G19: S | N19: Independence Terminal | O19: Independence, KS | Q19: 231 | R19: Raw Mill System #1
G20: T | N20: Indianapolis Terminal | O20: Indianapolis, IN | Q20: 232 | R20: Raw Mill System #2
G21: U | N21: Jeffersonville Terminal | O21: Jefferson, IN | Q21: 233 | R21: Raw Mill System #3
G22: V | N22: Joliet Terminal | O22: Joliet, IL | Q22: 234 | R22: Raw Mill System #4
G23: W | N23: Knoxville Terminal | O23: Knoxville, TN | Q23: 241 | R23: Blending / Kiln Feed
G24: Y | N24: Little Rock Terminal | O24: Little Rock, AR | Q24: 300 | R24: Clinker Burning
G25: Z | N25: Maryneal Cement | O25: Maryneal, TX | Q25: 301 | R25: Kiln System #1
N26: Memphis LSI Terminal | O26: Memphis, TN | Q26: 302 | R26: Kiln System #2
N27: Memphis RC Terminal | O27: Memphis, TN | Q27: 303 | R27: Kiln System #3
N28: Milwaukee Terminal | O28: Milwaukee, WI | Q28: 304 | R28: Kiln System #4
N29: Mina Terminal | O29: Atlanta, GA | Q29: 305 | R29: Kiln Dedusting
N30: Nashville (LSI) Terminal | O30: Nashville, TN | Q30: 330 | R30: Clinker Conveying & Storage
N31: Nashville (RC) Terminal | O31: Nashville, TN | Q31: 351 | R31: Coal/Coke Mill System #1
N32: Natchez Terminal | O32: Natchez, MS | Q32: 352 | R32: Coal/Coke Mill System #2
N33: New Orleans Terminal | O33: New Orleans, LA | Q33: 353 | R33: Coal/Coke Mill System #3
N34: Oglesby Cement | O34: Oglesby, IL | Q34: 354 | R34: Coal/Coke Mill System #4
N35: Oklahoma City Terminal | O35: Del City, OK | Q35: 355 | R35: Coal/Coke Unloading, Conveying & Storage
N36: Orange Terminal | O36: Orange, TX | Q36: 460 | R36: Waste Fuels
N37: Paducah Terminal | O37: Paducah, KY | Q37: 461 | R37: Waste Fuel - Liquids
... N45: Wichita Terminal | O45: Bel Aire, KS | Q45: 483 | R45: non-identified type to be assigned
Q46: 484 | R46: non-identified type to be assigned
Q47: 485 | R47: Oxygen Enrichment
...
